[2021-10-10 17:11:08,415] {taskinstance.py:903} INFO - Dependencies all met for <TaskInstance: example_passing_params_via_test_command.also_run_this 2021-10-09T00:33:00+00:00 [queued]>
[2021-10-10 17:11:08,420] {taskinstance.py:903} INFO - Dependencies all met for <TaskInstance: example_passing_params_via_test_command.also_run_this 2021-10-09T00:33:00+00:00 [queued]>
[2021-10-10 17:11:08,420] {taskinstance.py:1095} INFO - 
--------------------------------------------------------------------------------
[2021-10-10 17:11:08,420] {taskinstance.py:1096} INFO - Starting attempt 1 of 1
[2021-10-10 17:11:08,420] {taskinstance.py:1097} INFO - 
--------------------------------------------------------------------------------
[2021-10-10 17:11:08,428] {taskinstance.py:1115} INFO - Executing <Task(BashOperator): also_run_this> on 2021-10-09T00:33:00+00:00
[2021-10-10 17:11:08,430] {standard_task_runner.py:52} INFO - Started process 17344 to run task
[2021-10-10 17:11:08,433] {standard_task_runner.py:76} INFO - Running: ['airflow', 'tasks', 'run', 'example_passing_params_via_test_command', 'also_run_this', '2021-10-09T00:33:00+00:00', '--job-id', '294', '--pool', 'default_pool', '--raw', '--subdir', '/usr/local/lib/python3.8/dist-packages/airflow/example_dags/example_passing_params_via_test_command.py', '--cfg-path', '/tmp/tmpbvje8z4b', '--error-file', '/tmp/tmprckq4a8w']
[2021-10-10 17:11:08,433] {standard_task_runner.py:77} INFO - Job 294: Subtask also_run_this
[2021-10-10 17:11:08,456] {logging_mixin.py:109} INFO - Running <TaskInstance: example_passing_params_via_test_command.also_run_this 2021-10-09T00:33:00+00:00 [running]> on host abd
[2021-10-10 17:11:08,475] {taskinstance.py:1463} ERROR - Task failed with exception
Traceback (most recent call last):
  File "/usr/local/lib/python3.8/dist-packages/airflow/models/taskinstance.py", line 1165, in _run_raw_task
    self._prepare_and_execute_task_with_callbacks(context, task)
  File "/usr/local/lib/python3.8/dist-packages/airflow/models/taskinstance.py", line 1246, in _prepare_and_execute_task_with_callbacks
    self.render_templates(context=context)
  File "/usr/local/lib/python3.8/dist-packages/airflow/models/taskinstance.py", line 1755, in render_templates
    self.task.render_template_fields(context)
  File "/usr/local/lib/python3.8/dist-packages/airflow/models/baseoperator.py", line 997, in render_template_fields
    self._do_render_template_fields(self, self.template_fields, context, jinja_env, set())
  File "/usr/local/lib/python3.8/dist-packages/airflow/models/baseoperator.py", line 1010, in _do_render_template_fields
    rendered_content = self.render_template(content, context, jinja_env, seen_oids)
  File "/usr/local/lib/python3.8/dist-packages/airflow/models/baseoperator.py", line 1047, in render_template
    return jinja_env.from_string(content).render(**context)
  File "/home/abd/.local/lib/python3.8/site-packages/jinja2/environment.py", line 1090, in render
    self.environment.handle_exception()
  File "/home/abd/.local/lib/python3.8/site-packages/jinja2/environment.py", line 832, in handle_exception
    reraise(*rewrite_traceback_stack(source=source))
  File "/home/abd/.local/lib/python3.8/site-packages/jinja2/_compat.py", line 28, in reraise
    raise value.with_traceback(tb)
  File "<template>", line 2, in top-level template code
jinja2.exceptions.UndefinedError: 'dict object' has no attribute 'foo'
[2021-10-10 17:11:08,477] {taskinstance.py:1506} INFO - Marking task as FAILED. dag_id=example_passing_params_via_test_command, task_id=also_run_this, execution_date=20211009T003300, start_date=20211010T141108, end_date=20211010T141108
[2021-10-10 17:11:08,524] {local_task_job.py:151} INFO - Task exited with return code 1
[2021-10-10 17:11:08,534] {local_task_job.py:261} INFO - 0 downstream tasks scheduled from follow-on schedule check
